from fastapi import FastAPI, HTTPException
from celery import Celery
import requests
app = FastAPI()
MANAGEMENT_API_URL = "https://www.myadmin.com/api"
celery_app = Celery(
    "tasks",
    broker="redis://localhost:6379/0",
    backend="redis://localhost:6379/0"
)

@app.post("/schedule-task")
def schedule_task(payload: dict):
    instructions = payload.get("instructions", [])
    task = celery_app.send_task("tasks.execute_task", args=[instructions])
    return {"task_id": task.id}

@celery_app.task(name="tasks.execute_task")
def execute_task(instructions):
    results = []
    for instruction in instructions:
        # 执行 ADB 操作逻辑
        pass
    return results
def fetch_task_status(task_id: str):
    """
    从管理端获取任务状态
    """
    try:
        response = requests.get(f"{MANAGEMENT_API_URL}/task-status/{task_id}")
        response.raise_for_status()
        return response.json()
    except requests.exceptions.RequestException as e:
        return {"status": "error", "message": f"获取任务状态失败：{e}"}